<mujoco model="G1 Track">
  <include file="../../common.xml"/>

  <compiler angle="radian" meshdir="../../menagerie/unitree_g1/assets" autolimits="true"/>

  <option timestep="0.005"/>

  <size memory="1M"/>

  <custom>
    <!-- Planner settings -->
    <numeric name="agent_planner" data="2" />
    <numeric name="agent_horizon" data="0.5" />
    <numeric name="agent_timestep" data="0.01" />
    <numeric name="sampling_spline_points" data="8" />
    <numeric name="sampling_exploration" data="0.1" />
    <numeric name="sampling_trajectories" data="64" />

    <!-- Trajectory settings -->
    <text name="trajectory_path" data="walk_test.csv" />
    <numeric name="trajectory_fps" data="30" />
  </custom>

  <default>
    <default class="g1">
      <joint damping="0.5" armature="0.01" frictionloss="0.1"/>
    </default>
  </default>

  <asset>
    <mesh file="pelvis.STL"/>
    <mesh file="pelvis_contour_link.STL"/>
    <mesh file="left_hip_pitch_link.STL"/>
    <mesh file="left_hip_roll_link.STL"/>
    <mesh file="left_hip_yaw_link.STL"/>
    <mesh file="left_knee_link.STL"/>
    <mesh file="left_ankle_pitch_link.STL"/>
    <mesh file="left_ankle_roll_link.STL"/>
    <mesh file="right_hip_pitch_link.STL"/>
    <mesh file="right_hip_roll_link.STL"/>
    <mesh file="right_hip_yaw_link.STL"/>
    <mesh file="right_knee_link.STL"/>
    <mesh file="right_ankle_pitch_link.STL"/>
    <mesh file="right_ankle_roll_link.STL"/>
    <mesh file="torso_link.STL"/>
    <mesh file="head_link.STL"/>
    <mesh file="logo_link.STL"/>
    <mesh file="left_shoulder_pitch_link.STL"/>
    <mesh file="left_shoulder_roll_link.STL"/>
    <mesh file="left_shoulder_yaw_link.STL"/>
    <mesh file="left_elbow_pitch_link.STL"/>
    <mesh file="left_elbow_roll_link.STL"/>
    <mesh file="left_palm_link.STL"/>
    <mesh file="left_zero_link.STL"/>
    <mesh file="left_one_link.STL"/>
    <mesh file="left_two_link.STL"/>
    <mesh file="left_three_link.STL"/>
    <mesh file="left_four_link.STL"/>
    <mesh file="left_five_link.STL"/>
    <mesh file="left_six_link.STL"/>
    <mesh file="right_shoulder_pitch_link.STL"/>
    <mesh file="right_shoulder_roll_link.STL"/>
    <mesh file="right_shoulder_yaw_link.STL"/>
    <mesh file="right_elbow_pitch_link.STL"/>
    <mesh file="right_elbow_roll_link.STL"/>
    <mesh file="right_palm_link.STL"/>
    <mesh file="right_zero_link.STL"/>
    <mesh file="right_one_link.STL"/>
    <mesh file="right_two_link.STL"/>
    <mesh file="right_three_link.STL"/>
    <mesh file="right_four_link.STL"/>
    <mesh file="right_five_link.STL"/>
    <mesh file="right_six_link.STL"/>
  </asset>

  <worldbody>
    <geom name="floor" size="50 50 0.05" type="plane" material="blue_grid" condim="3" friction="1 0.005 0.0001"/>

    <body name="pelvis" pos="0 0 0.755" childclass="g1">
      <inertial pos="0 0 -0.07605" quat="1 0 -0.000405289 0" mass="2.86" diaginertia="0.0079143 0.0069837 0.0059404"/>
      <freejoint name="floating_base_joint"/>
      <geom type="mesh" mesh="pelvis" contype="0" conaffinity="0" density="0"/>
      <geom type="mesh" mesh="pelvis"/>
      <geom type="mesh" mesh="pelvis_contour_link" contype="0" conaffinity="0" density="0"/>

      <!-- Left Leg -->
      <body name="left_hip_pitch_link" pos="0 0.06445 -0.1027" quat="0.984807 0 -0.17365 0">
        <inertial pos="0.001962 0.049392 -0.000941" quat="0.420735 0.907025 -0.0155675 -0.00670646" mass="1.299" diaginertia="0.00138785 0.000955478 0.00086947"/>
        <joint name="left_hip_pitch_joint" axis="0 1 0" range="-2.35 3.05"/>
        <geom type="mesh" mesh="left_hip_pitch_link" contype="0" conaffinity="0" density="0"/>
        <geom type="mesh" mesh="left_hip_pitch_link"/>
        <body name="left_hip_roll_link" pos="0 0.0523 0">
          <inertial pos="0.024757 -0.001036 -0.086323" quat="0.977498 -0.00692636 0.210181 0.0165269" mass="1.446" diaginertia="0.00244106 0.00230425 0.00142899"/>
          <joint name="left_hip_roll_joint" axis="1 0 0" range="-0.26 2.53"/>
          <geom type="mesh" mesh="left_hip_roll_link" contype="0" conaffinity="0" density="0"/>
          <geom type="mesh" mesh="left_hip_roll_link"/>
          <body name="left_hip_yaw_link" pos="0.01966 -0.0012139 -0.1241">
            <inertial pos="-0.053554 -0.011477 -0.14067" quat="0.645099 0.15885 0.202109 0.71956" mass="2.052" diaginertia="0.0114475 0.0107868 0.00214501"/>
            <joint name="left_hip_yaw_joint" axis="0 0 1" range="-2.75 2.75"/>
            <geom type="mesh" mesh="left_hip_yaw_link" contype="0" conaffinity="0" density="0"/>
            <geom type="mesh" mesh="left_hip_yaw_link"/>
            <body name="left_knee_link" pos="-0.078292 -0.0017335 -0.177225" quat="0.967714 0 0.252052 0">
              <inertial pos="0.005505 0.006534 -0.116629" quat="0.799234 -0.0128894 0.0354278 0.599836" mass="2.252" diaginertia="0.0127418 0.0124382 0.00192524"/>
              <joint name="left_knee_joint" axis="0 1 0" range="-0.33489 2.5449"/>
              <geom type="mesh" mesh="left_knee_link" contype="0" conaffinity="0" density="0"/>
              <geom size="0.015 0.075" pos="0.007 0.005 -0.15" type="cylinder"/>
              <body name="left_ankle_pitch_link" pos="0 0.0040687 -0.30007" quat="0.99678 0 -0.0801788 0">
                <inertial pos="-0.007269 0 0.011137" quat="0.603053 0.369225 0.369225 0.603053" mass="0.074" diaginertia="1.89e-05 1.40805e-05 6.9195e-06"/>
                <joint name="left_ankle_pitch_joint" axis="0 1 0" range="-0.68 0.73"/>
                <geom type="mesh" mesh="left_ankle_pitch_link" contype="0" conaffinity="0" density="0"/>
                <geom type="mesh" mesh="left_ankle_pitch_link"/>
                <body name="left_ankle_roll_link" pos="0 0 -0.017558">
                  <inertial pos="0.024762 2e-05 -0.012526" quat="0.000771333 0.734476 0.000921291 0.678634" mass="0.391" diaginertia="0.00110394 0.0010657 0.000149255"/>
                  <joint name="left_ankle_roll_joint" axis="1 0 0" range="-0.2618 0.2618"/>
                  <geom type="mesh" mesh="left_ankle_roll_link" contype="0" conaffinity="0" density="0"/>
                  <geom pos="-0.06 0.02 -0.03" type="sphere" size="0.001"/>
                  <geom pos="-0.06 -0.02 -0.03" type="sphere" size="0.001"/>
                  <geom pos="0.13 0.02 -0.03" type="sphere" size="0.001"/>
                  <geom pos="0.13 -0.02 -0.03" type="sphere" size="0.001"/>
                </body>
              </body>
            </body>
          </body>
        </body>
      </body>

      <!-- Right Leg -->
      <body name="right_hip_pitch_link" pos="0 -0.06445 -0.1027" quat="0.984807 0 -0.17365 0">
        <inertial pos="0.001962 -0.049392 -0.000941" quat="0.907025 0.420735 0.00670646 0.0155675" mass="1.299" diaginertia="0.00138785 0.000955478 0.00086947"/>
        <joint name="right_hip_pitch_joint" axis="0 1 0" range="-2.35 3.05"/>
        <geom type="mesh" mesh="right_hip_pitch_link" contype="0" conaffinity="0" density="0"/>
        <geom type="mesh" mesh="right_hip_pitch_link"/>
        <body name="right_hip_roll_link" pos="0 -0.0523 0">
          <inertial pos="0.024757 0.001036 -0.086323" quat="0.977498 0.00692636 0.210181 -0.0165269" mass="1.446" diaginertia="0.00244106 0.00230425 0.00142899"/>
          <joint name="right_hip_roll_joint" axis="1 0 0" range="-2.53 0.26"/>
          <geom type="mesh" mesh="right_hip_roll_link" contype="0" conaffinity="0" density="0"/>
          <geom type="mesh" mesh="right_hip_roll_link"/>
          <body name="right_hip_yaw_link" pos="0.01966 0.0012139 -0.1241">
            <inertial pos="-0.053554 0.011477 -0.14067" quat="0.71956 0.202109 0.15885 0.645099" mass="2.052" diaginertia="0.0114475 0.0107868 0.00214501"/>
            <joint name="right_hip_yaw_joint" axis="0 0 1" range="-2.75 2.75"/>
            <geom type="mesh" mesh="right_hip_yaw_link" contype="0" conaffinity="0" density="0"/>
            <geom type="mesh" mesh="right_hip_yaw_link"/>
            <body name="right_knee_link" pos="-0.078292 0.0017335 -0.177225" quat="0.967714 0 0.252052 0">
              <inertial pos="0.005505 -0.006534 -0.116629" quat="0.599836 0.0354278 -0.0128894 0.799234" mass="2.252" diaginertia="0.0127418 0.0124382 0.00192524"/>
              <joint name="right_knee_joint" axis="0 1 0" range="-0.33489 2.5449"/>
              <geom type="mesh" mesh="right_knee_link" contype="0" conaffinity="0" density="0"/>
              <geom size="0.015 0.075" pos="0.007 -0.005 -0.15" type="cylinder"/>
              <body name="right_ankle_pitch_link" pos="0 -0.0040687 -0.30007" quat="0.99678 0 -0.0801788 0">
                <inertial pos="-0.007269 0 0.011137" quat="0.603053 0.369225 0.369225 0.603053" mass="0.074" diaginertia="1.89e-05 1.40805e-05 6.9195e-06"/>
                <joint name="right_ankle_pitch_joint" axis="0 1 0" range="-0.68 0.73"/>
                <geom type="mesh" mesh="right_ankle_pitch_link" contype="0" conaffinity="0" density="0"/>
                <geom type="mesh" mesh="right_ankle_pitch_link"/>
                <body name="right_ankle_roll_link" pos="0 0 -0.017558">
                  <inertial pos="0.024762 -2e-05 -0.012526" quat="-0.000771333 0.734476 -0.000921291 0.678634" mass="0.391" diaginertia="0.00110394 0.0010657 0.000149255"/>
                  <joint name="right_ankle_roll_joint" axis="1 0 0" range="-0.2618 0.2618"/>
                  <geom type="mesh" mesh="right_ankle_roll_link" contype="0" conaffinity="0" density="0"/>
                  <geom pos="-0.06 0.02 -0.03" type="sphere" size="0.001"/>
                  <geom pos="-0.06 -0.02 -0.03" type="sphere" size="0.001"/>
                  <geom pos="0.13 0.02 -0.03" type="sphere" size="0.001"/>
                  <geom pos="0.13 -0.02 -0.03" type="sphere" size="0.001"/>
                </body>
              </body>
            </body>
          </body>
        </body>
      </body>

      <!-- Torso -->
      <body name="torso_link">
        <inertial pos="0.00187791 0.00229457 0.208747" quat="0.999957 0.00624375 -0.00636707 -0.0026338" mass="7.52036" diaginertia="0.12848 0.111753 0.0350394"/>
        <joint name="torso_joint" axis="0 0 1" range="-2.618 2.618"/>
        <geom type="mesh" mesh="torso_link" contype="0" conaffinity="0" density="0"/>
        <geom type="mesh" mesh="torso_link"/>
        <geom type="mesh" mesh="head_link" contype="0" conaffinity="0" density="0"/>
        <geom type="mesh" mesh="head_link"/>
        <geom type="mesh" mesh="logo_link" contype="0" conaffinity="0" density="0"/>
        <geom type="mesh" mesh="logo_link"/>

        <!-- Left Arm -->
        <body name="left_shoulder_pitch_link" pos="-0.0025 0.10396 0.25928" quat="0.990268 0.139172 0 0">
          <inertial pos="-0.001431 0.048811 0.001304" quat="0.786417 0.588396 -0.180543 0.0523639" mass="0.713" diaginertia="0.000466421 0.000440181 0.000410999"/>
          <joint name="left_shoulder_pitch_joint" axis="0 1 0" range="-2.9671 2.7925"/>
          <geom type="mesh" mesh="left_shoulder_pitch_link" contype="0" conaffinity="0" density="0"/>
          <geom type="mesh" mesh="left_shoulder_pitch_link"/>
          <body name="left_shoulder_roll_link" pos="0 0.052 0" quat="0.990268 -0.139172 0 0">
            <inertial pos="-0.003415 0.006955 -0.064598" quat="0.70683 0.0105364 0.00575207 0.707282" mass="0.642" diaginertia="0.000683514 0.000616029 0.000372857"/>
            <joint name="left_shoulder_roll_joint" axis="1 0 0" range="-1.5882 2.2515"/>
            <geom type="mesh" mesh="left_shoulder_roll_link" contype="0" conaffinity="0" density="0"/>
            <geom size="0.03 0.015" pos="-0.004 0.006 -0.053" type="cylinder"/>
            <body name="left_shoulder_yaw_link" pos="-0.00354 0.0062424 -0.1032">
              <inertial pos="0.000375 -0.00444 -0.072374" quat="0.903834 -0.0374183 0.00985482 0.42613" mass="0.713" diaginertia="0.000977874 0.000964661 0.000379065"/>
              <joint name="left_shoulder_yaw_joint" axis="0 0 1" range="-2.618 2.618"/>
              <geom type="mesh" mesh="left_shoulder_yaw_link" contype="0" conaffinity="0" density="0"/>
              <geom type="mesh" mesh="left_shoulder_yaw_link"/>
              <body name="left_elbow_pitch_link" pos="0 0.00189 -0.0855">
                <inertial pos="0.064497 0.002873 0" quat="0.582347 0.582495 0.400893 0.401069" mass="0.601" diaginertia="0.00049549 0.0004712 0.00025371"/>
                <joint name="left_elbow_pitch_joint" axis="0 1 0" range="-0.2268 3.4208"/>
                <geom type="mesh" mesh="left_elbow_pitch_link" contype="0" conaffinity="0" density="0"/>
                <geom type="mesh" mesh="left_elbow_pitch_link"/>
                <body name="left_elbow_roll_link" pos="0.1 0 0">
                  <inertial pos="0.133814 0.00147121 0.000265832" quat="0.496781 0.497877 0.498782 0.506502" mass="0.50826" diaginertia="0.00239763 0.00226639 0.000285577"/>
                  <joint name="left_elbow_roll_joint" axis="1 0 0" range="-2.0943 2.0943"/>
                  <geom type="mesh" mesh="left_elbow_roll_link" contype="0" conaffinity="0" density="0"/>
                  <geom type="mesh" mesh="left_elbow_roll_link"/>
                  <geom pos="0.12 0 0" type="mesh" mesh="left_palm_link" contype="0" conaffinity="0" density="0"/>
                  <geom pos="0.12 0 0" type="mesh" mesh="left_palm_link"/>
                </body>
              </body>
            </body>
          </body>
        </body>

        <!-- Right Arm -->
        <body name="right_shoulder_pitch_link" pos="-0.0025 -0.10396 0.25928" quat="0.990268 -0.139172 0 0">
          <inertial pos="-0.001431 -0.048811 0.001304" quat="0.588396 0.786417 -0.0523639 0.180543" mass="0.713" diaginertia="0.000466421 0.000440181 0.000410999"/>
          <joint name="right_shoulder_pitch_joint" axis="0 1 0" range="-2.9671 2.7925"/>
          <geom type="mesh" mesh="right_shoulder_pitch_link" contype="0" conaffinity="0" density="0"/>
          <geom type="mesh" mesh="right_shoulder_pitch_link"/>
          <body name="right_shoulder_roll_link" pos="0 -0.052 0" quat="0.990268 0.139172 0 0">
            <inertial pos="-0.003415 -0.006955 -0.064598" quat="0.707282 0.00575207 0.0105364 0.70683" mass="0.642" diaginertia="0.000683514 0.000616029 0.000372857"/>
            <joint name="right_shoulder_roll_joint" axis="1 0 0" range="-2.2515 1.5882"/>
            <geom type="mesh" mesh="right_shoulder_roll_link" contype="0" conaffinity="0" density="0"/>
            <geom size="0.03 0.015" pos="-0.004 -0.006 -0.053" type="cylinder"/>
            <body name="right_shoulder_yaw_link" pos="-0.00354 -0.0062424 -0.1032">
              <inertial pos="0.000375 0.00444 -0.072374" quat="0.42613 0.00985482 -0.0374183 0.903834" mass="0.713" diaginertia="0.000977874 0.000964661 0.000379065"/>
              <joint name="right_shoulder_yaw_joint" axis="0 0 1" range="-2.618 2.618"/>
              <geom type="mesh" mesh="right_shoulder_yaw_link" contype="0" conaffinity="0" density="0"/>
              <geom type="mesh" mesh="right_shoulder_yaw_link"/>
              <body name="right_elbow_pitch_link" pos="0 -0.00189 -0.0855">
                <inertial pos="0.064497 -0.002873 0" quat="0.401069 0.400893 0.582495 0.582347" mass="0.601" diaginertia="0.00049549 0.0004712 0.00025371"/>
                <joint name="right_elbow_pitch_joint" axis="0 1 0" range="-0.2268 3.4208"/>
                <geom type="mesh" mesh="right_elbow_pitch_link" contype="0" conaffinity="0" density="0"/>
                <geom type="mesh" mesh="right_elbow_pitch_link"/>
                <body name="right_elbow_roll_link" pos="0.1 0 0">
                  <inertial pos="0.133814 -0.00147121 0.000265832" quat="0.506502 0.498782 0.497877 0.496781" mass="0.50826" diaginertia="0.00239763 0.00226639 0.000285577"/>
                  <joint name="right_elbow_roll_joint" axis="1 0 0" range="-2.0943 2.0943"/>
                  <geom type="mesh" mesh="right_elbow_roll_link" contype="0" conaffinity="0" density="0"/>
                  <geom type="mesh" mesh="right_elbow_roll_link"/>
                  <geom pos="0.12 0 0" type="mesh" mesh="right_palm_link" contype="0" conaffinity="0" density="0"/>
                  <geom pos="0.12 0 0" type="mesh" mesh="right_palm_link"/>
                </body>
              </body>
            </body>
          </body>
        </body>
      </body>
    </body>
  </worldbody>

  <actuator>
    <motor name="left_hip_pitch_joint" joint="left_hip_pitch_joint" ctrlrange="-88 88"/>
    <motor name="left_hip_roll_joint" joint="left_hip_roll_joint" ctrlrange="-88 88"/>
    <motor name="left_hip_yaw_joint" joint="left_hip_yaw_joint" ctrlrange="-88 88"/>
    <motor name="left_knee_joint" joint="left_knee_joint" ctrlrange="-139 139"/>
    <motor name="left_ankle_pitch_joint" joint="left_ankle_pitch_joint" ctrlrange="-40 40"/>
    <motor name="left_ankle_roll_joint" joint="left_ankle_roll_joint" ctrlrange="-40 40"/>
    <motor name="right_hip_pitch_joint" joint="right_hip_pitch_joint" ctrlrange="-88 88"/>
    <motor name="right_hip_roll_joint" joint="right_hip_roll_joint" ctrlrange="-88 88"/>
    <motor name="right_hip_yaw_joint" joint="right_hip_yaw_joint" ctrlrange="-88 88"/>
    <motor name="right_knee_joint" joint="right_knee_joint" ctrlrange="-139 139"/>
    <motor name="right_ankle_pitch_joint" joint="right_ankle_pitch_joint" ctrlrange="-40 40"/>
    <motor name="right_ankle_roll_joint" joint="right_ankle_roll_joint" ctrlrange="-40 40"/>
    <motor name="torso_joint" joint="torso_joint" ctrlrange="-88 88"/>
    <motor name="left_shoulder_pitch_joint" joint="left_shoulder_pitch_joint" ctrlrange="-20 20"/>
    <motor name="left_shoulder_roll_joint" joint="left_shoulder_roll_joint" ctrlrange="-20 20"/>
    <motor name="left_shoulder_yaw_joint" joint="left_shoulder_yaw_joint" ctrlrange="-20 20"/>
    <motor name="left_elbow_pitch_joint" joint="left_elbow_pitch_joint" ctrlrange="-20 20"/>
    <motor name="left_elbow_roll_joint" joint="left_elbow_roll_joint" ctrlrange="-20 20"/>
    <motor name="right_shoulder_pitch_joint" joint="right_shoulder_pitch_joint" ctrlrange="-20 20"/>
    <motor name="right_shoulder_roll_joint" joint="right_shoulder_roll_joint" ctrlrange="-20 20"/>
    <motor name="right_shoulder_yaw_joint" joint="right_shoulder_yaw_joint" ctrlrange="-20 20"/>
    <motor name="right_elbow_pitch_joint" joint="right_elbow_pitch_joint" ctrlrange="-20 20"/>
    <motor name="right_elbow_roll_joint" joint="right_elbow_roll_joint" ctrlrange="-20 20"/>
  </actuator>

  <!-- 23 joints, 23 actuators -->
  <sensor>
    <user name="Joint Vel." dim="23" user="0 0.01 0.0 0.1" />
    <user name="Control" dim="23" user="3 0.001 0 0.01 0.1" />
    <user name="Root Pos" dim="3" user="6 10.0 0.0 100.0 0.1" />
    <user name="Root Ori" dim="3" user="6 5.0 0.0 50.0 0.1" />
    <user name="Joint Pos" dim="23" user="6 1.0 0.0 10.0 0.1" />
    <framepos name="trace0" objtype="body" objname="pelvis"/>
  </sensor>

  <keyframe>
    <key name="stand" qpos="0 0 0.755 1 0 0 0 0 0 0 0 0 0 0 0 0 0 0 0 0 0 0 0 0 0 0 0 0 0 0"/>
  </keyframe>
</mujoco>
